Workbook
Name ConnectionInfo: 'Spool List'!#REF!
Name ObjectInfo: 'Spool List'!#REF!

Sheet Spool List
I1: =SUBTOTAL(9,NavDataRegion[Total Qty]) -> 1314 | N1: =SUBTOTAL(9,NavDataRegion[Total Wt2]) -> 255449.14
A2: Project Code | B2: Drawing No. | C2: Spool No | D2: Vlookup | E2: Box No | F2: MSN no. | G2: Paint System | H2: Description | I2: Total Qty | J2: PDI Date | K2: Packing Date | L2: Packing Status | M2: Dispatched Date | N2: Total Wt2 | O2: Inch Dia | P2: Spool Size | Q2: REMARK
A3: TJ/25-26/184 | B3: V17551-PIND-0081 | C3: V17551-PIND-0081-L18 | D3: =VLOOKUP(C:C,Vlookup!A:A,1,0) -> #N/A | E3: 17 | G3: P5 | H3: Spool | I3: 1 | J3: 46101 | K3: 46104 | L3: DISPATCHED | M3: 45754 | N3: =VLOOKUP(NavDataRegion[[#This Row],[Spool No]],[1]Sheet2!$B:$U,20,0) -> 60.38 | O3: 0 | P3: 4
A4: TJ/25-26/184 | B4: V17551-PIND-0096 | C4: V17551-PIND-0096-L22 | D4: =VLOOKUP(C:C,Vlookup!A:A,1,0) -> #N/A | E4: 17 | G4: P5 | H4: Spool | I4: 1 | J4: 46101 | K4: 46104 | L4: DISPATCHED | M4: 45754 | N4: =VLOOKUP(NavDataRegion[[#This Row],[Spool No]],[1]Sheet2!$B:$U,20,0) -> 33 | O4: 0 | P4: 4
A5: TJ/25-26/184 | B5: V17551-PIND-0085 | C5: V17551-PIND-0085-03 | D5: =VLOOKUP(C:C,Vlookup!A:A,1,0) -> #N/A | E5: 18 | G5: P5,P1 | H5: Spool | I5: 1 | J5: 46111 | K5: 46113 | L5: DISPATCHED | M5: 45754 | N5: =VLOOKUP(NavDataRegion[[#This Row],[Spool No]],[1]Sheet2!$B:$U,20,0) -> 156.84353 | O5: 8 | P5: 4
A6: TJ/25-26/184 | B6: V17551-PIND-0157 | C6: V17551-PIND-0157-01 | D6: =VLOOKUP(C:C,Vlookup!A:A,1,0) -> #N/A | E6: 5 | G6: P5 | H6: Spool | I6: 1 | J6: 46010 | K6: 46013 | L6: DISPATCHED | M6: 46090 | N6: =VLOOKUP(NavDataRegion[[#This Row],[Spool No]],[1]Sheet2!$B:$U,20,0) -> 2.94703 | O6: 2.5 | P6: 2.5
A7: TJ/25-26/184 | B7: V17551-PIND-0158 | C7: V17551-PIND-0158-01 | D7: =VLOOKUP(C:C,Vlookup!A:A,1,0) -> #N/A | E7: 5 | G7: P5 | H7: Spool | I7: 1 | J7: 46010 | K7: 46013 | L7: DISPATCHED | M7: 46090 | N7: =VLOOKUP(NavDataRegion[[#This Row],[Spool No]],[1]Sheet2!$B:$U,20,0) -> 3.39202 | O7: 2.5 | P7: 2.5
A8: TJ/25-26/184 | B8: V17551-PIND-0306 | C8: V17551-PIND-0306-01 | D8: =VLOOKUP(C:C,Vlookup!A:A,1,0) -> #N/A | E8: 16 | G8: P1 | H8: Spool | I8: 1 | J8: 46113 | K8: 46118 | L8: DISPATCHED | M8: 46167 | N8: =VLOOKUP(NavDataRegion[[#This Row],[Spool No]],[1]Sheet2!$B:$U,20,0) -> 4.29562 | O8: 1.5 | P8: 0.5
A9: TJ/25-26/184 | B9: V17551-PIND-0157 | C9: V17551-PIND-0157-02 | D9: =VLOOKUP(C:C,Vlookup!A:A,1,0) -> #N/A | E9: 9 | G9: P5 | H9: Spool | I9: 1 | J9: 46049 | K9: 46050 | L9: DISPATCHED | M9: 46091 | N9: =VLOOKUP(NavDataRegion[[#This Row],[Spool No]],[1]Sheet2!$B:$U,20,0) -> 67.294676 | O9: 10.5 | P9: 2.5
A10: TJ/25-26/184 | B10: V17551-PIND-0015 | C10: V17551-PIND-0015-01 | D10: =VLOOKUP(C:C,Vlookup!A:A,1,0) -> #N/A | E10: 2 | G10: P5 | H10: Spool | I10: 1 | J10: 45981 | K10: 45982 | L10: DISPATCHED | M10: 46090 | N10: =VLOOKUP(NavDataRegion[[#This Row],[Spool No]],[1]Sheet2!$B:$U,20,0) -> 166.63912 | O10: 150 | P10: 6
A11: TJ/25-26/184 | B11: V17551-PIND-0158 | C11: V17551-PIND-0158-03 | D11: =VLOOKUP(C:C,Vlookup!A:A,1,0) -> #N/A | E11: 6 | G11: P5 | H11: Spool | I11: 1 | J11: 46029 | K11: 46029 | L11: DISPATCHED | M11: 46091 | N11: =VLOOKUP(NavDataRegion[[#This Row],[Spool No]],[1]Sheet2!$B:$U,20,0) -> 9.6399458 | O11: 8 | P11: 2.5
A12: TJ/25-26/184 | B12: V17551-PIND-0493 | C12: V17551-PIND-0493-01 | D12: =VLOOKUP(C:C,Vlookup!A:A,1,0) -> #N/A | E12: 16 | G12: P5 | H12: Spool | I12: 1 | J12: 46113 | K12: 46118 | L12: DISPATCHED | M12: 46167 | N12: =VLOOKUP(NavDataRegion[[#This Row],[Spool No]],[1]Sheet2!$B:$U,20,0) -> 0.2673 | O12: 0 | P12: 0.5
A13: TJ/25-26/184 | B13: V17551-PIND-0157 | C13: V17551-PIND-0157-03 | D13: =VLOOKUP(C:C,Vlookup!A:A,1,0) -> #N/A | E13: 6 | G13: P5 | H13: Spool | I13: 1 | J13: 46017 | K13: 46027 | L13: DISPATCHED | M13: 46091 | N13: =VLOOKUP(NavDataRegion[[#This Row],[Spool No]],[1]Sheet2!$B:$U,20,0) -> 42.52057 | O13: 12.5 | P13: 2.5
A14: TJ/25-26/184 | B14: V17551-PIND-0019 | C14: V17551-PIND-0019-01 | D14: =VLOOKUP(C:C,Vlookup!A:A,1,0) -> #N/A | E14: 1 | G14: P5 | H14: Spool | I14: 1 | J14: 45981 | K14: 45982 | L14: DISPATCHED | M14: 46090 | N14: =VLOOKUP(NavDataRegion[[#This Row],[Spool No]],[1]Sheet2!$B:$U,20,0) -> 170.67448 | O14: 84 | P14: 6
... A17: TJ/25-26/184 | B17: V17551-PIND-0494 | C17: V17551-PIND-0494-01 | D17: =VLOOKUP(C:C,Vlookup!A:A,1,0) -> #N/A | E17: 16 | G17: P5 | H17: Spool | I17: 1 | J17: 46113 | K17: 46118 | L17: DISPATCHED | M17: 46167 | N17: =VLOOKUP(NavDataRegion[[#This Row],[Spool No]],[1]Sheet2!$B:$U,20,0) -> 10.89102 | O17: 2.5 | P17: 0.5
A18: TJ/25-26/184 | B18: V17551-PIND-0100 | C18: V17551-PIND-0100-01 | D18: =VLOOKUP(C:C,Vlookup!A:A,1,0) -> #N/A | E18: 3 | F18: S-5136 | G18: P5,P1 | H18: Spool | I18: 1 | J18: 46003 | K18: 46006 | L18: DISPATCHED | M18: 46090 | N18: =VLOOKUP(NavDataRegion[[#This Row],[Spool No]],[1]Sheet2!$B:$U,20,0) -> 59.301555 | O18: 18.5 | P18: 3
A19: TJ/25-26/184 | B19: V17551-PIND-0101 | C19: V17551-PIND-0101-01 | D19: =VLOOKUP(C:C,Vlookup!A:A,1,0) -> #N/A | E19: 3 | G19: P5,P1 | H19: Spool | I19: 1 | J19: 45995 | K19: 45999 | L19: DISPATCHED | M19: 46090 | N19: =VLOOKUP(NavDataRegion[[#This Row],[Spool No]],[1]Sheet2!$B:$U,20,0) -> 24.22229 | O19: 6.5 | P19: 3
A20: TJ/25-26/184 | B20: V17551-PIND-0107 | C20: V17551-PIND-0107-01 | D20: =VLOOKUP(C:C,Vlookup!A:A,1,0) -> #N/A | E20: 9 | G20: P5,P1 | H20: Spool | I20: 1 | J20: 46051 | K20: 46055 | L20: DISPATCHED | M20: 46091 | N20: =VLOOKUP(NavDataRegion[[#This Row],[Spool No]],[1]Sheet2!$B:$U,20,0) -> 148.18462 | O20: 17.5 | P20: 3
A21: TJ/25-26/184 | B21: V17551-PIND-0133 | C21: V17551-PIND-0133-01 | D21: =VLOOKUP(C:C,Vlookup!A:A,1,0) -> #N/A | E21: 7 | G21: P5 | H21: Spool | I21: 1 | J21: 46043 | K21: 46043 | L21: DISPATCHED | M21: 46091 | N21: =VLOOKUP(NavDataRegion[[#This Row],[Spool No]],[1]Sheet2!$B:$U,20,0) -> 21.73017 | O21: 21.5 | P21: 3
A22: TJ/25-26/184 | B22: V17551-PIND-0147 | C22: V17551-PIND-0147-08 | D22: =VLOOKUP(C:C,Vlookup!A:A,1,0) -> #N/A | E22: 5 | F22: S-5221 | G22: P5 | H22: Spool | I22: 1 | J22: 46015 | K22: 46016 | L22: DISPATCHED | M22: 46090 | N22: =VLOOKUP(NavDataRegion[[#This Row],[Spool No]],[1]Sheet2!$B:$U,20,0) -> 23.0565 | O22: 6 | P22: 3
A23: TJ/25-26/184 | B23: V17551-PIND-0029 | C23: V17551-PIND-0029-01 | D23: =VLOOKUP(C:C,Vlookup!A:A,1,0) -> #N/A | E23: 1 | G23: P5 | H23: Spool | I23: 1 | J23: 45981 | K23: 45982 | L23: DISPATCHED | M23: 46090 | N23: =VLOOKUP(NavDataRegion[[#This Row],[Spool No]],[1]Sheet2!$B:$U,20,0) -> 170.67448 | O23: 84 | P23: 6
A24: TJ/25-26/184 | B24: V17551-PIND-0345 | C24: V17551-PIND-0345-01 | D24: =VLOOKUP(C:C,Vlookup!A:A,1,0) -> #N/A | E24: 14 | G24: P5 | H24: Spool | I24: 1 | J24: 46105 | K24: 46106 | L24: DISPATCHED | M24: 45754 | N24: =VLOOKUP(NavDataRegion[[#This Row],[Spool No]],[1]Sheet2!$B:$U,20,0) -> 12.43926 | O24: 2.5 | P24: 0.5
A25: TJ/25-26/184 | B25: V17551-PIND-0100 | C25: V17551-PIND-0100-02 | D25: =VLOOKUP(C:C,Vlookup!A:A,1,0) -> #N/A | E25: 1 | F25: S-5137 | G25: P5 | H25: Spool | I25: 1 | J25: 45975 | K25: 45764 | L25: DISPATCHED | M25: 46090 | N25: =VLOOKUP(NavDataRegion[[#This Row],[Spool No]],[1]Sheet2!$B:$U,20,0) -> 40.19929 | O25: 9 | P25: 3
A26: TJ/25-26/184 | B26: V17551-PIND-0301 | C26: V17551-PIND-0301-02 | D26: =VLOOKUP(C:C,Vlookup!A:A,1,0) -> #N/A | E26: 14 | G26: P5 | H26: Spool | I26: 1 | J26: 46098 | K26: 46099 | L26: DISPATCHED | M26: 45754 | N26: =VLOOKUP(NavDataRegion[[#This Row],[Spool No]],[1]Sheet2!$B:$U,20,0) -> 28.30184 | O26: 7 | P26: 1
A27: TJ/25-26/184 | B27: V17551-PIND-0144 | C27: V17551-PIND-0144-01 | D27: =VLOOKUP(C:C,Vlookup!A:A,1,0) -> #N/A | E27: 1 | G27: P1 | H27: Spool | I27: 1 | J27: 45975 | K27: 45764 | L27: DISPATCHED | M27: 46090 | N27: =VLOOKUP(NavDataRegion[[#This Row],[Spool No]],[1]Sheet2!$B:$U,20,0) -> 56.85704 | O27: 4 | P27: 4
A28: TJ/25-26/184 | B28: V17551-PIND-0107 | C28: V17551-PIND-0107-02 | D28: =VLOOKUP(C:C,Vlookup!A:A,1,0) -> #N/A | E28: 6 | G28: P5,P1 | H28: Spool | I28: 1 | J28: 46017 | K28: 46027 | L28: DISPATCHED | M28: 46091 | N28: =VLOOKUP(NavDataRegion[[#This Row],[Spool No]],[1]Sheet2!$B:$U,20,0) -> 142.49667 | O28: 9 | P28: 3
A29: TJ/25-26/184 | B29: V17551-PIND-0099 | C29: V17551-PIND-0099-02 | D29: =VLOOKUP(C:C,Vlookup!A:A,1,0) -> #N/A | E29: 1 | F29: S-5135 | G29: P5 | H29: Spool | I29: 1 | J29: 45975 | K29: 45764 | L29: DISPATCHED | M29: 46090 | N29: =VLOOKUP(NavDataRegion[[#This Row],[Spool No]],[1]Sheet2!$B:$U,20,0) -> 30.7036 | O29: 8 | P29: 4
A30: TJ/25-26/184 | B30: V17551-PIND-0133 | C30: V17551-PIND-0133-02 | D30: =VLOOKUP(C:C,Vlookup!A:A,1,0) -> #N/A | E30: 5 | G30: P5,P1 | H30: Spool | I30: 1 | J30: 46015 | K30: 46016 | L30: DISPATCHED | M30: 46090 | N30: =VLOOKUP(NavDataRegion[[#This Row],[Spool No]],[1]Sheet2!$B:$U,20,0) -> 96.11096 | O30: 19 | P30: 3
A31: TJ/25-26/184 | B31: V17551-PIND-0037 | C31: V17551-PIND-0037-01 | D31: =VLOOKUP(C:C,Vlookup!A:A,1,0) -> #N/A | E31: 2 | G31: P5 | H31: Spool | I31: 1 | J31: 45981 | K31: 45982 | L31: DISPATCHED | M31: 46090 | N31: =VLOOKUP(NavDataRegion[[#This Row],[Spool No]],[1]Sheet2!$B:$U,20,0) -> 170.67448 | O31: 84 | P31: 6
A32: TJ/25-26/184 | B32: V17551-PIND-0147 | C32: V17551-PIND-0147-07 | D32: =VLOOKUP(C:C,Vlookup!A:A,1,0) -> #N/A | E32: 7 | F32: S-5222 | G32: P5,P1 | H32: Spool | I32: 1 | J32: 46043 | K32: 46043 | L32: DISPATCHED | M32: 46091 | N32: =VLOOKUP(NavDataRegion[[#This Row],[Spool No]],[1]Sheet2!$B:$U,20,0) -> 226.08061 | O32: 16 | P32: 3
A33: TJ/25-26/184 | B33: V17551-PIND-0039 | C33: V17551-PIND-0039-01 | D33: =VLOOKUP(C:C,Vlookup!A:A,1,0) -> #N/A | E33: 1 | G33: P5 | H33: Spool | I33: 1 | J33: 45981 | K33: 45982 | L33: DISPATCHED | M33: 46090 | N33: =VLOOKUP(NavDataRegion[[#This Row],[Spool No]],[1]Sheet2!$B:$U,20,0) -> 170.67448 | O33: 84 | P33: 6
A34: TJ/25-26/184 | B34: V17551-PIND-0467 | C34: V17551-PIND-0467-01 | D34: =VLOOKUP(C:C,Vlookup!A:A,1,0) -> #N/A | E34: 14 | G34: P5 | H34: Spool | I34: 1 | J34: 46100 | K34: 46101 | L34: DISPATCHED | M34: 45754 | N34: =VLOOKUP(NavDataRegion[[#This Row],[Spool No]],[1]Sheet2!$B:$U,20,0) -> 3.96892 | O34: 2 | P34: 0.5
A35: TJ/25-26/184 | B35: V17551-PIND-0144 | C35: V17551-PIND-0144-02 | D35: =VLOOKUP(C:C,Vlookup!A:A,1,0) -> #N/A | E35: 1 | G35: P1 | H35: Spool | I35: 1 | J35: 45975 | K35: 45764 | L35: DISPATCHED | M35: 46090 | N35: =VLOOKUP(NavDataRegion[[#This Row],[Spool No]],[1]Sheet2!$B:$U,20,0) -> 47.96432 | O35: 8 | P35: 4
A36: TJ/25-26/184 | B36: V17551-PIND-0468 | C36: V17551-PIND-0468-01 | D36: =VLOOKUP(C:C,Vlookup!A:A,1,0) -> #N/A | E36: 14 | G36: P5 | H36: Spool | I36: 1 | J36: 46100 | K36: 46101 | L36: DISPATCHED | M36: 45754 | N36: =VLOOKUP(NavDataRegion[[#This Row],[Spool No]],[1]Sheet2!$B:$U,20,0) -> 0.95672 | O36: 1 | P36: 0.5
A37: TJ/25-26/184 | B37: V17551-PIND-0101 | C37: V17551-PIND-0101-03 | D37: =VLOOKUP(C:C,Vlookup!A:A,1,0) -> #N/A | E37: 3 | G37: P5,P1 | H37: Spool | I37: 1 | J37: 46003 | K37: 46006 | L37: DISPATCHED | M37: 46090 | N37: =VLOOKUP(NavDataRegion[[#This Row],[Spool No]],[1]Sheet2!$B:$U,20,0) -> 69.704162 | O37: 13 | P37: 3
A38: TJ/25-26/184 | B38: V17551-PIND-0107 | C38: V17551-PIND-0107-03 | D38: =VLOOKUP(C:C,Vlookup!A:A,1,0) -> #N/A | E38: 7 | G38: P5,P1 | H38: Spool | I38: 1 | J38: 46029 | K38: 45665 | L38: DISPATCHED | M38: 46091 | N38: =VLOOKUP(NavDataRegion[[#This Row],[Spool No]],[1]Sheet2!$B:$U,20,0) -> 129.03655 | O38: 15 | P38: 3
A39: TJ/25-26/184 | B39: V17551-PIND-0045 | C39: V17551-PIND-0045-01 | D39: =VLOOKUP(C:C,Vlookup!A:A,1,0) -> #N/A | E39: 1 | G39: P5 | H39: Spool | I39: 1 | J39: 45981 | K39: 45982 | L39: DISPATCHED | M39: 46090 | N39: =VLOOKUP(NavDataRegion[[#This Row],[Spool No]],[1]Sheet2!$B:$U,20,0) -> 170.67448 | O39: 84 | P39: 6
A40: TJ/25-26/184 | B40: V17551-PIND-0133 | C40: V17551-PIND-0133-03 | D40: =VLOOKUP(C:C,Vlookup!A:A,1,0) -> #N/A | E40: 11 | G40: P5,P1 | H40: Spool | I40: 1 | J40: 46064 | K40: 46069 | L40: DISPATCHED | M40: 46105 | N40: =VLOOKUP(NavDataRegion[[#This Row],[Spool No]],[1]Sheet2!$B:$U,20,0) -> 55.92815 | O40: 13 | P40: 3
A41: TJ/25-26/184 | B41: V17551-PIND-0047 | C41: V17551-PIND-0047-01 | D41: =VLOOKUP(C:C,Vlookup!A:A,1,0) -> #N/A | E41: 1 | G41: P5 | H41: Spool | I41: 1 | J41: 45981 | K41: 45982 | L41: DISPATCHED | M41: 46090 | N41: =VLOOKUP(NavDataRegion[[#This Row],[Spool No]],[1]Sheet2!$B:$U,20,0) -> 170.67448 | O41: 84 | P41: 6
A42: TJ/25-26/184 | B42: V17551-PIND-0147 | C42: V17551-PIND-0147-06 | D42: =VLOOKUP(C:C,Vlookup!A:A,1,0) -> #N/A | E42: 7 | F42: S-5223 | G42: P5,P1 | H42: Spool | I42: 1 | J42: 46036 | K42: 46041 | L42: DISPATCHED | M42: 46091 | N42: =VLOOKUP(NavDataRegion[[#This Row],[Spool No]],[1]Sheet2!$B:$U,20,0) -> 171.76553 | O42: 22 | P42: 3
...

Sheet Summary
B2: TJ/25-26/184 / Vogt Power
B3: Box No. | C3: Status | D3: QTY | E3: Net WT. | F3: Dispatch Date | G3: Container No. | H3: Seal No. | I3: VPI package no. | J3: LBP/SBP
B4: 1 | C4: Dispatched | D4: 41 | E4: 9278 | F4: 46090 | G4: JXLU7835341 | H4: A4251282344 | I4: NRGCB-HRSG5-VPI-DEE-93280-0001 | J4: Large Bore
B5: 2 | C5: Dispatched | D5: 56 | E5: 10295 | F5: 46090 | G5: ZCSU7460137 | H5: A4251282341 | I5: NRGCB-HRSG5-VPI-DEE-93280-0002 | J5: Large Bore
B6: 3 | C6: Dispatched | D6: 48 | E6: 12332 | F6: 46090 | G6: ZCSU7955250 | H6: A4251282348 | I6: NRGCB-HRSG5-VPI-DEE-93280-0003 | J6: Large Bore
B7: 4 | C7: Dispatched | D7: 36 | E7: 11022 | F7: 46090 | G7: ZCSU7490321 | H7: A4251282354 | I7: NRGCB-HRSG5-VPI-DEE-93280-0004 | J7: Large Bore
B8: 5 | C8: Dispatched | D8: 66 | E8: 8836 | F8: 46090 | G8: ZCSU7202765 | H8: A4251282359 | I8: NRGCB-HRSG5-VPI-DEE-93280-0005 | J8: Large Bore
B9: 6 | C9: Dispatched | D9: 48 | E9: 9303 | F9: 46091 | G9: FSCU8167312 | H9: A4251282396 | I9: NRGCB-HRSG5-VPI-DEE-93280-0006 | J9: Large Bore
B10: 7 | C10: Dispatched | D10: 38 | E10: 10387 | F10: 46091 | G10: JXLU6325338 | H10: A4251282389 | I10: NRGCB-HRSG5-VPI-DEE-93280-0007 | J10: Large Bore
B11: 8 | C11: Dispatched | D11: 18 | E11: 9567 | F11: 46091 | G11: JXLU4400520 | H11: A4251282407 | I11: NRGCB-HRSG5-VPI-DEE-93280-0008 | J11: Large Bore
B12: 9 | C12: Dispatched | D12: 20 | E12: 11346 | F12: 46091 | G12: ZCSU6617793 | H12: A4251282420 | I12: NRGCB-HRSG5-VPI-DEE-93280-0009 | J12: Large Bore
B13: 10 | C13: Dispatched | D13: 4 | E13: 11959 | F13: 46091 | G13: TCNU6081129 | H13: A4251282432 | I13: NRGCB-HRSG5-VPI-DEE-93280-0010 | J13: Large Bore
B14: 11 | C14: Dispatched | D14: 14 | E14: 11576 | F14: 46105 | G14: TGHU6285187 | H14: A4251468303 | I14: NRGCB-HRSG5-VPI-DEE-93280-0011 | J14: Large Bore
B15: 12 | C15: Dispatched | D15: 31 | E15: 14518 | F15: 46105 | G15: ZCSU6524094 | H15: A4251468308 | I15: NRGCB-HRSG5-VPI-DEE-93280-0012 | J15: Large Bore
... B27: 24 | C27: Dispatched | D27: 5 | E27: 13480 | F27: 46185 | G27: ZCSU6660043 | H27: A4251469549 | I27: NRGCB-HRSG5-VPI-DEE-93280-0024 | J27: Large Bore
B28: 25 | C28: Dispatched | D28: 2 | E28: 228 | F28: 46227 | I28: By Air Shipped | J28: Small Bore
C29: TOTAL | D29: =SUM(D4:D28) -> 1314 | E29: =SUM(E4:E28) -> 259090

Sheet Vlookup
A1: V17551-PIND-0372-02
A2: V17551-PIND-0373-03
